Workbook

Sheet Русский
A1: Задание. Предприятие начало производство новой продукции. На основании данных таблицы разработать смету затрат на производство продукции по элементам и определить структуру затрат. Сформировать отпускную цену продукции с учетом планируемого уровня рентабельности. Рассчитать точку безубыточности производства изделия, предварительно определив условно-переменные и условно-постоянные затраты. Построить график безубыточности. Рассчитать кромку безопасности
A2: Показатели | B2: Варианты
B3: 1 | C3: 2 | D3: 3 | E3: 4 | F3: 5 | G3: 6 | H3: 7 | I3: 8 | J3: 9 | K3: 10
A4: 1. Годовой выпуск продукции, шт. | B4: 4800 | C4: 6000 | D4: 7200 | E4: 50000 | F4: 4500 | G4: 6300 | H4: 7000 | I4: 6000 | J4: 5500 | K4: 7400
A5: 2. Затраты сырья, материалов на 1 шт, $ | B5: 30 | C5: 22 | D5: 24 | E5: 35 | F5: 27 | G5: 28 | H5: 35 | I5: 40 | J5: 37 | K5: 19
A6: 3. Затраты энергии на производство продукции, КВт*ч/шт | B6: 95 | C6: 80 | D6: 140 | E6: 160 | F6: 155 | G6: 130 | H6: 240 | I6: 270 | J6: 360 | K6: 150
A7: 4. Цена 1 КВт*ч, $ | B7: 0.35 | C7: 0.37 | D7: 0.38 | E7: 0.4 | F7: 0.39 | G7: 0.38 | H7: 0.35 | I7: 0.37 | J7: 0.36 | K7: 0.42
A8: 5. Расходы на освещение и отопление здания, $/год | B8: 2400 | C8: 5000 | D8: 6000 | E8: 4000 | F8: 4500 | G8: 3950 | H8: 4000 | I8: 5050 | J8: 5000 | K8: 4700
A9: 6. Заработная плата производственных рабочих, $/год | B9: 7500 | C9: 9500 | D9: 9000 | E9: 8500 | F9: 6500 | G9: 6500 | H9: 7000 | I9: 5000 | J9: 4500 | K9: 6000
A10: 7. Заработная плата административного персонала, $/год | B10: 5500 | C10: 6500 | D10: 6000 | E10: 5000 | F10: 4000 | G10: 8580 | H10: 3140 | I10: 3560 | J10: 4680 | K10: 7340
A11: 8. Амортизация зданий, оборудования$/год | B11: 65600 | C11: 38400 | D11: 54600 | E11: 62500 | F11: 72800 | G11: 19840 | H11: 15270 | I11: 16450 | J11: 17150 | K11: 19270
A12: 9. Затраты на научные исследования, $/год | B12: 9000 | C12: 5500 | D12: 6000 | E12: 8000 | F12: 4500 | G12: 2200 | H12: 2300 | I12: 1800 | J12: 2050 | K12: 2000
A13: 10. Плата процентов по кредитам банка, $/год | B13: 26000 | C13: 21000 | D13: 17000 | E13: 25000 | F13: 19000 | G13: 19000 | H13: 10000 | I13: 17000 | J13: 13000 | K13: 11000
A14: 11. Оплата услуг информационных и аудиторских компаний, $/год | B14: 20000 | C14: 18000 | D14: 15000 | E14: 21000 | F14: 14000 | G14: 15000 | H14: 2800 | I14: 4000 | J14: 1900 | K14: 3500
A15: 12. Оплата рекламных услуг, $/год | B15: 25000 | C15: 6500 | D15: 2200 | E15: 1400 | F15: 3100 | G15: 150 | H15: 10000 | I15: 11000 | J15: 12000 | K15: 14000
... A17: 14. Рентабельность продукции, % | B17: 25 | C17: 12 | D17: 18 | E17: 20 | F17: 16 | G17: 10 | H17: 13 | I17: 15 | J17: 17 | K17: 18
A18: ЭЛЕМЕНТЫ ЗАТРАТ
A19: 1. Материальные и энергетические затраты, руб. (п2*п1+п3*п4*п1+п5) | G19: =G5*G4+G7*G6*G4+G8 -> 491570
A20: 2. Заработная плата, руб. ((п5+п6)) | G20: =G9+G10 -> 15080
A21: 3. Отчисления в ФСЗН, руб. (26% от ФОТ) | G21: =G20*0.26 -> 3920.8
A22: 4. Амортизационные отчисления, руб. (п8) | G22: =G11 -> 19840
A23: 5. Прочие, руб. (п9+п10+п11+п12+п13) | G23: =SUM(G12:G16) -> 53350
A24: ИТОГО, $ | G24: =SUM(G19:G23) -> 583760.8
A25: 6. Себестоимость, $/изделие | G25: =G24/G4 -> 92.660444
A26: 7. Цена, $/изделие | G26: =G25+(G25*G17/100) -> 101.92649
A27: 8. Условно-постоянные (УПР) расходы, тыс. $ (п5+п7+п7*26%+п8+п9+п10+п11+п12) | G27: =G8+G10+G10*0.26+G11+G12+G13+G14+G15 -> 70950.8
A28: 9. Условно-переменные на 1ш т, $ (Собщ-УПР)/В | G28: =(G24-G27)/G4 -> 81.398413
A29: Точка окупаемости, шт | G29: =G27/(G26-G28) -> 3456.281
A30: СТРУКТУРА ЗАТРАТ, %
A31: 1. Материальные затраты | G31: =G19/G24*100 -> 84.207436
A32: 2. Фонд оплаты труда работников | G32: =G20/G24*100 -> 2.5832499
A33: 3. Отчисления в ФСЗН | G33: =G21/G24*100 -> 0.67164496
A34: 4. Амортизационные отчисления | G34: =G22/G24*100 -> 3.3986523
A35: 5. Прочие | G35: =G23/G24*100 -> 9.1390172
A36: ИТОГО | G36: =SUM(G31:G35) -> 100
A37: Запас финансовой прочности, $ | G37: ='6'!G9 -> 289.85029
A38: Запас финансовой прочности, % | G38: ='6'!H9 -> 45.138397
A40: Методические указания
A41: 1. Смета затрат на производство продукции (на весь объем) формируется в соответствии с Основными положениями по составу затрат, включаемых в себестоимость продукции на основании исходных данных.
A42: Материальные затраты включают стоимость сырья, материалов, энергии, платы за пользование природными ресурсами
...

Sheet English
A1: Exercise 4
A2: The company began production of new products. Develop cost estimates for production of products by element and determine the cost structure. Calculate the selling price of products taking into account the planned level of profitability. Calculate the break-even point for the production of a new product
A3: Indicators | B3: Options
B4: 1 | C4: 2 | D4: 3 | E4: 4 | F4: 5 | G4: 6 | H4: 7 | I4: 8 | J4: 9 | K4: 10
A5: 1. The volume of production per year, products/year | B5: 4800 | C5: 6000 | D5: 7200 | E5: 50000 | F5: 4500 | G5: 6300 | H5: 7000 | I5: 6000 | J5: 5500 | K5: 7400
A6: 2. Material costs, $/product | B6: 30 | C6: 22 | D6: 24 | E6: 35 | F6: 27 | G6: 28 | H6: 35 | I6: 40 | J6: 37 | K6: 19
A7: 3. Energy consumption for production, kWh/product | B7: 95 | C7: 80 | D7: 140 | E7: 160 | F7: 155 | G7: 130 | H7: 240 | I7: 270 | J7: 360 | K7: 150
A8: 4. Price 1 kWh, $ | B8: 0.35 | C8: 0.37 | D8: 0.38 | E8: 0.4 | F8: 0.39 | G8: 0.38 | H8: 0.35 | I8: 0.37 | J8: 0.36 | K8: 0.42
A9: 5. Costs for lighting and heating of the building, $/year | B9: 2400 | C9: 5000 | D9: 6000 | E9: 4000 | F9: 4500 | G9: 3950 | H9: 4000 | I9: 5050 | J9: 5000 | K9: 4700
A10: 6. Salaries of production workers, $/year | B10: 7500 | C10: 9500 | D10: 9000 | E10: 8500 | F10: 6500 | G10: 6500 | H10: 7000 | I10: 5000 | J10: 4500 | K10: 6000
A11: 7. Salaries of administrative staff, $/year | B11: 5500 | C11: 6500 | D11: 6000 | E11: 5000 | F11: 4000 | G11: 8580 | H11: 3140 | I11: 3560 | J11: 4680 | K11: 7340
A12: 8. Amortization of buildings, equipment, $/year | B12: 65600 | C12: 38400 | D12: 54600 | E12: 62500 | F12: 72800 | G12: 19840 | H12: 15270 | I12: 16450 | J12: 17150 | K12: 19270
A13: 9. Research costs, $/year | B13: 9000 | C13: 5500 | D13: 6000 | E13: 8000 | F13: 4500 | G13: 2200 | H13: 2300 | I13: 1800 | J13: 2050 | K13: 2000
A14: 10. Payment of interest on bank loans, $/year | B14: 26000 | C14: 21000 | D14: 17000 | E14: 25000 | F14: 19000 | G14: 19000 | H14: 10000 | I14: 17000 | J14: 13000 | K14: 11000
A15: 11. Payment for services of information and audit companies, $/year | B15: 20000 | C15: 18000 | D15: 15000 | E15: 21000 | F15: 14000 | G15: 15000 | H15: 2800 | I15: 4000 | J15: 1900 | K15: 3500
A16: 12. Payment for advertising services, $/year | B16: 25000 | C16: 6500 | D16: 2200 | E16: 1400 | F16: 3100 | G16: 150 | H16: 10000 | I16: 11000 | J16: 12000 | K16: 14000
... A18: 14. Profitability (profit) of products, % | B18: 25 | C18: 12 | D18: 18 | E18: 20 | F18: 16 | G18: 10 | H18: 13 | I18: 15 | J18: 17 | K18: 18
A19: COST ELEMENTS, $
A20: 1. Material and energy costs (п2*п1+п3*п4*п1+п5)
A21: 2. Employees' wages ((п5+п6))
A22: 3. Contributions for social needs (26% от заработной платы)
A23: 4. Amortization (п8)
A24: 5. Other costs (п9+п10+п11+п12+п13)
A25: TOTAL, $
A26: 6. Cost, $/product
A27: 7. Price, $/product
A28: 8. Fixed costs, $ (п5+п7+п7*26%+п8+п9+п10+п11+п12)
A29: 9. Variable costs, $/product
A30: Payback point (break-even production volume), products
... A65: A margin of financial strength is considered to be a margin of safety greater than 30%

Sheet График
A1: Пример (условный)
A2: Объем производства, шт | B2: Зпост, тыс. руб. | C2: Зпер, тыс. руб/шт | D2: Зитого | E2: Выручка.общ, тыс. руб. | F2: Прибыль, тыс. руб. | G2: Кромка безопасности, тыс. руб. (Выручка ф(пл) - Выручка в точке безуб) | H2: Кромка безопасности, % (Кромка безопасности, тыс. руб./Выручка, тыс. руб.*100)
A3: 10000 | B3: =$B$34 -> 8000 | C3: =$B$35/1000*A3 -> 7000 | D3: =B3+C3 -> 15000 | E3: =A3*$B$36/1000 -> 9900 | F3: =E3-D3 -> -5100 | G3: =E3-$E$13 -> -17410.345 | H3: =G3/E3*100 -> -175.86207
A4: 12000 | B4: =$B$34 -> 8000 | C4: =$B$35/1000*A4 -> 8400 | D4: =B4+C4 -> 16400 | E4: =A4*$B$36/1000 -> 11880 | F4: =E4-D4 -> -4520 | G4: =E4-$E$13 -> -15430.345 | H4: =G4/E4*100 -> -129.88506
A5: 14000 | B5: =$B$34 -> 8000 | C5: =$B$35/1000*A5 -> 9800 | D5: =B5+C5 -> 17800 | E5: =A5*$B$36/1000 -> 13860 | F5: =E5-D5 -> -3940 | G5: =E5-$E$13 -> -13450.345 | H5: =G5/E5*100 -> -97.044335
A6: 16000 | B6: =$B$34 -> 8000 | C6: =$B$35/1000*A6 -> 11200 | D6: =B6+C6 -> 19200 | E6: =A6*$B$36/1000 -> 15840 | F6: =E6-D6 -> -3360 | G6: =E6-$E$13 -> -11470.345 | H6: =G6/E6*100 -> -72.413793
A7: 18000 | B7: =$B$34 -> 8000 | C7: =$B$35/1000*A7 -> 12600 | D7: =B7+C7 -> 20600 | E7: =A7*$B$36/1000 -> 17820 | F7: =E7-D7 -> -2780 | G7: =E7-$E$13 -> -9490.3448 | H7: =G7/E7*100 -> -53.256705
A8: 19000 | B8: =$B$34 -> 8000 | C8: =$B$35/1000*A8 -> 13300 | D8: =B8+C8 -> 21300 | E8: =A8*$B$36/1000 -> 18810 | F8: =E8-D8 -> -2490 | G8: =E8-$E$13 -> -8500.3448 | H8: =G8/E8*100 -> -45.190563
A9: 20000 | B9: =$B$34 -> 8000 | C9: =$B$35/1000*A9 -> 14000 | D9: =B9+C9 -> 22000 | E9: =A9*$B$36/1000 -> 19800 | F9: =E9-D9 -> -2200 | G9: =E9-$E$13 -> -7510.3448 | H9: =G9/E9*100 -> -37.931034
A10: 22000 | B10: =$B$34 -> 8000 | C10: =$B$35/1000*A10 -> 15400 | D10: =B10+C10 -> 23400 | E10: =A10*$B$36/1000 -> 21780 | F10: =E10-D10 -> -1620 | G10: =E10-$E$13 -> -5530.3448 | H10: =G10/E10*100 -> -25.39185
A11: 24000 | B11: =$B$34 -> 8000 | C11: =$B$35/1000*A11 -> 16800 | D11: =B11+C11 -> 24800 | E11: =A11*$B$36/1000 -> 23760 | F11: =E11-D11 -> -1040 | G11: =E11-$E$13 -> -3550.3448 | H11: =G11/E11*100 -> -14.942529
A12: 26000 | B12: =$B$34 -> 8000 | C12: =$B$35/1000*A12 -> 18200 | D12: =B12+C12 -> 26200 | E12: =A12*$B$36/1000 -> 25740 | F12: =E12-D12 -> -460 | G12: =E12-$E$13 -> -1570.3448 | H12: =G12/E12*100 -> -6.1007958
A13: =B33 -> 27586.207 | B13: =$B$34 -> 8000 | C13: =$B$35/1000*A13 -> 19310.345 | D13: =B13+C13 -> 27310.345 | E13: =A13*$B$36/1000 -> 27310.345 | F13: =E13-D13 -> 0 | G13: =E13-$E$13 -> 0 | H13: =G13/E13*100 -> 0
A14: 30000 | B14: =$B$34 -> 8000 | C14: =$B$35/1000*A14 -> 21000 | D14: =B14+C14 -> 29000 | E14: =A14*$B$36/1000 -> 29700 | F14: =E14-D14 -> 700 | G14: =E14-$E$13 -> 2389.6552 | H14: =G14/E14*100 -> 8.045977
A15: 32000 | B15: =$B$34 -> 8000 | C15: =$B$35/1000*A15 -> 22400 | D15: =B15+C15 -> 30400 | E15: =A15*$B$36/1000 -> 31680 | F15: =E15-D15 -> 1280 | G15: =E15-$E$13 -> 4369.6552 | H15: =G15/E15*100 -> 13.793103
A16: 34000 | B16: =$B$34 -> 8000 | C16: =$B$35/1000*A16 -> 23800 | D16: =B16+C16 -> 31800 | E16: =A16*$B$36/1000 -> 33660 | F16: =E16-D16 -> 1860 | G16: =E16-$E$13 -> 6349.6552 | H16: =G16/E16*100 -> 18.864097
A17: 36000 | B17: =$B$34 -> 8000 | C17: =$B$35/1000*A17 -> 25200 | D17: =B17+C17 -> 33200 | E17: =A17*$B$36/1000 -> 35640 | F17: =E17-D17 -> 2440 | G17: =E17-$E$13 -> 8329.6552 | H17: =G17/E17*100 -> 23.371648
A18: 38000 | B18: =$B$34 -> 8000 | C18: =$B$35/1000*A18 -> 26600 | D18: =B18+C18 -> 34600 | E18: =A18*$B$36/1000 -> 37620 | F18: =E18-D18 -> 3020 | G18: =E18-$E$13 -> 10309.655 | H18: =G18/E18*100 -> 27.404719
A19: 40000 | B19: =$B$34 -> 8000 | C19: =$B$35/1000*A19 -> 28000 | D19: =B19+C19 -> 36000 | E19: =A19*$B$36/1000 -> 39600 | F19: =E19-D19 -> 3600 | G19: =E19-$E$13 -> 12289.655 | H19: =G19/E19*100 -> 31.034483
A20: 42000 | B20: =$B$34 -> 8000 | C20: =$B$35/1000*A20 -> 29400 | D20: =B20+C20 -> 37400 | E20: =A20*$B$36/1000 -> 41580 | F20: =E20-D20 -> 4180 | G20: =E20-$E$13 -> 14269.655 | H20: =G20/E20*100 -> 34.318555
A21: 44000 | B21: =$B$34 -> 8000 | C21: =$B$35/1000*A21 -> 30800 | D21: =B21+C21 -> 38800 | E21: =A21*$B$36/1000 -> 43560 | F21: =E21-D21 -> 4760 | G21: =E21-$E$13 -> 16249.655 | H21: =G21/E21*100 -> 37.304075
A22: 46000 | B22: =$B$34 -> 8000 | C22: =$B$35/1000*A22 -> 32200 | D22: =B22+C22 -> 40200 | E22: =A22*$B$36/1000 -> 45540 | F22: =E22-D22 -> 5340 | G22: =E22-$E$13 -> 18229.655 | H22: =G22/E22*100 -> 40.029985
A23: 48000 | B23: =$B$34 -> 8000 | C23: =$B$35/1000*A23 -> 33600 | D23: =B23+C23 -> 41600 | E23: =A23*$B$36/1000 -> 47520 | F23: =E23-D23 -> 5920 | G23: =E23-$E$13 -> 20209.655 | H23: =G23/E23*100 -> 42.528736
A24: 50000 | B24: =$B$34 -> 8000 | C24: =$B$35/1000*A24 -> 35000 | D24: =B24+C24 -> 43000 | E24: =A24*$B$36/1000 -> 49500 | F24: =E24-D24 -> 6500 | G24: =E24-$E$13 -> 22189.655 | H24: =G24/E24*100 -> 44.827586
A25: 52000 | B25: =$B$34 -> 8000 | C25: =$B$35/1000*A25 -> 36400 | D25: =B25+C25 -> 44400 | E25: =A25*$B$36/1000 -> 51480 | F25: =E25-D25 -> 7080 | G25: =E25-$E$13 -> 24169.655 | H25: =G25/E25*100 -> 46.949602
... A29: 60000 | B29: =$B$34 -> 8000 | C29: =$B$35/1000*A29 -> 42000 | D29: =B29+C29 -> 50000 | E29: =A29*$B$36/1000 -> 59400 | F29: =E29-D29 -> 9400 | G29: =E29-$E$13 -> 32089.655 | H29: =G29/E29*100 -> 54.022989
A31: Пример (условный)
A32: Исходные данные для разработки графика
A33: В без, шт | B33: =B34*1000/(B36-B35) -> 27586.207
A34: Зпост, тыс. руб. | B34: 8000
A35: Зпер, руб./шт | B35: 700
A36: Ц, руб./шт | B36: 990
A37: Выпуск ф, шт | B37: 38000

Sheet Graph
A1: Example (conditional)
A2: The volume of production, products | B2: Fixed costs, thousand $ | C2: Variable costs, thousand $ | D2: Total cost, thousand $ | E2: Revenue from product sales, thousand $ | F2: Profit, thousand $ | G2: Financial strength margin, thousand $ (Actual revenue from product sales - Revenue from product sales at the break-even point) | H2: Financial strength margin, % (Financial strength margin/Revenue from product sales*100)
A3: 10000 | B3: =$B$34 -> 8000 | C3: =$B$35/1000*A3 -> 7000 | D3: =B3+C3 -> 15000 | E3: =A3*$B$36/1000 -> 9900 | F3: =E3-D3 -> -5100 | G3: =E3-$E$13 -> -17410.345 | H3: =G3/E3*100 -> -175.86207
A4: 12000 | B4: =$B$34 -> 8000 | C4: =$B$35/1000*A4 -> 8400 | D4: =B4+C4 -> 16400 | E4: =A4*$B$36/1000 -> 11880 | F4: =E4-D4 -> -4520 | G4: =E4-$E$13 -> -15430.345 | H4: =G4/E4*100 -> -129.88506
A5: 14000 | B5: =$B$34 -> 8000 | C5: =$B$35/1000*A5 -> 9800 | D5: =B5+C5 -> 17800 | E5: =A5*$B$36/1000 -> 13860 | F5: =E5-D5 -> -3940 | G5: =E5-$E$13 -> -13450.345 | H5: =G5/E5*100 -> -97.044335
A6: 16000 | B6: =$B$34 -> 8000 | C6: =$B$35/1000*A6 -> 11200 | D6: =B6+C6 -> 19200 | E6: =A6*$B$36/1000 -> 15840 | F6: =E6-D6 -> -3360 | G6: =E6-$E$13 -> -11470.345 | H6: =G6/E6*100 -> -72.413793
A7: 18000 | B7: =$B$34 -> 8000 | C7: =$B$35/1000*A7 -> 12600 | D7: =B7+C7 -> 20600 | E7: =A7*$B$36/1000 -> 17820 | F7: =E7-D7 -> -2780 | G7: =E7-$E$13 -> -9490.3448 | H7: =G7/E7*100 -> -53.256705
A8: 19000 | B8: =$B$34 -> 8000 | C8: =$B$35/1000*A8 -> 13300 | D8: =B8+C8 -> 21300 | E8: =A8*$B$36/1000 -> 18810 | F8: =E8-D8 -> -2490 | G8: =E8-$E$13 -> -8500.3448 | H8: =G8/E8*100 -> -45.190563
A9: 20000 | B9: =$B$34 -> 8000 | C9: =$B$35/1000*A9 -> 14000 | D9: =B9+C9 -> 22000 | E9: =A9*$B$36/1000 -> 19800 | F9: =E9-D9 -> -2200 | G9: =E9-$E$13 -> -7510.3448 | H9: =G9/E9*100 -> -37.931034
A10: 22000 | B10: =$B$34 -> 8000 | C10: =$B$35/1000*A10 -> 15400 | D10: =B10+C10 -> 23400 | E10: =A10*$B$36/1000 -> 21780 | F10: =E10-D10 -> -1620 | G10: =E10-$E$13 -> -5530.3448 | H10: =G10/E10*100 -> -25.39185
A11: 24000 | B11: =$B$34 -> 8000 | C11: =$B$35/1000*A11 -> 16800 | D11: =B11+C11 -> 24800 | E11: =A11*$B$36/1000 -> 23760 | F11: =E11-D11 -> -1040 | G11: =E11-$E$13 -> -3550.3448 | H11: =G11/E11*100 -> -14.942529
A12: 26000 | B12: =$B$34 -> 8000 | C12: =$B$35/1000*A12 -> 18200 | D12: =B12+C12 -> 26200 | E12: =A12*$B$36/1000 -> 25740 | F12: =E12-D12 -> -460 | G12: =E12-$E$13 -> -1570.3448 | H12: =G12/E12*100 -> -6.1007958
A13: =B33 -> 27586.207 | B13: =$B$34 -> 8000 | C13: =$B$35/1000*A13 -> 19310.345 | D13: =B13+C13 -> 27310.345 | E13: =A13*$B$36/1000 -> 27310.345 | F13: =E13-D13 -> 0 | G13: =E13-$E$13 -> 0 | H13: =G13/E13*100 -> 0
A14: 30000 | B14: =$B$34 -> 8000 | C14: =$B$35/1000*A14 -> 21000 | D14: =B14+C14 -> 29000 | E14: =A14*$B$36/1000 -> 29700 | F14: =E14-D14 -> 700 | G14: =E14-$E$13 -> 2389.6552 | H14: =G14/E14*100 -> 8.045977
A15: 32000 | B15: =$B$34 -> 8000 | C15: =$B$35/1000*A15 -> 22400 | D15: =B15+C15 -> 30400 | E15: =A15*$B$36/1000 -> 31680 | F15: =E15-D15 -> 1280 | G15: =E15-$E$13 -> 4369.6552 | H15: =G15/E15*100 -> 13.793103
A16: 34000 | B16: =$B$34 -> 8000 | C16: =$B$35/1000*A16 -> 23800 | D16: =B16+C16 -> 31800 | E16: =A16*$B$36/1000 -> 33660 | F16: =E16-D16 -> 1860 | G16: =E16-$E$13 -> 6349.6552 | H16: =G16/E16*100 -> 18.864097
A17: 36000 | B17: =$B$34 -> 8000 | C17: =$B$35/1000*A17 -> 25200 | D17: =B17+C17 -> 33200 | E17: =A17*$B$36/1000 -> 35640 | F17: =E17-D17 -> 2440 | G17: =E17-$E$13 -> 8329.6552 | H17: =G17/E17*100 -> 23.371648
A18: 38000 | B18: =$B$34 -> 8000 | C18: =$B$35/1000*A18 -> 26600 | D18: =B18+C18 -> 34600 | E18: =A18*$B$36/1000 -> 37620 | F18: =E18-D18 -> 3020 | G18: =E18-$E$13 -> 10309.655 | H18: =G18/E18*100 -> 27.404719
A19: 40000 | B19: =$B$34 -> 8000 | C19: =$B$35/1000*A19 -> 28000 | D19: =B19+C19 -> 36000 | E19: =A19*$B$36/1000 -> 39600 | F19: =E19-D19 -> 3600 | G19: =E19-$E$13 -> 12289.655 | H19: =G19/E19*100 -> 31.034483
A20: 42000 | B20: =$B$34 -> 8000 | C20: =$B$35/1000*A20 -> 29400 | D20: =B20+C20 -> 37400 | E20: =A20*$B$36/1000 -> 41580 | F20: =E20-D20 -> 4180 | G20: =E20-$E$13 -> 14269.655 | H20: =G20/E20*100 -> 34.318555
A21: 44000 | B21: =$B$34 -> 8000 | C21: =$B$35/1000*A21 -> 30800 | D21: =B21+C21 -> 38800 | E21: =A21*$B$36/1000 -> 43560 | F21: =E21-D21 -> 4760 | G21: =E21-$E$13 -> 16249.655 | H21: =G21/E21*100 -> 37.304075
A22: 46000 | B22: =$B$34 -> 8000 | C22: =$B$35/1000*A22 -> 32200 | D22: =B22+C22 -> 40200 | E22: =A22*$B$36/1000 -> 45540 | F22: =E22-D22 -> 5340 | G22: =E22-$E$13 -> 18229.655 | H22: =G22/E22*100 -> 40.029985
A23: 48000 | B23: =$B$34 -> 8000 | C23: =$B$35/1000*A23 -> 33600 | D23: =B23+C23 -> 41600 | E23: =A23*$B$36/1000 -> 47520 | F23: =E23-D23 -> 5920 | G23: =E23-$E$13 -> 20209.655 | H23: =G23/E23*100 -> 42.528736
A24: 50000 | B24: =$B$34 -> 8000 | C24: =$B$35/1000*A24 -> 35000 | D24: =B24+C24 -> 43000 | E24: =A24*$B$36/1000 -> 49500 | F24: =E24-D24 -> 6500 | G24: =E24-$E$13 -> 22189.655 | H24: =G24/E24*100 -> 44.827586
A25: 52000 | B25: =$B$34 -> 8000 | C25: =$B$35/1000*A25 -> 36400 | D25: =B25+C25 -> 44400 | E25: =A25*$B$36/1000 -> 51480 | F25: =E25-D25 -> 7080 | G25: =E25-$E$13 -> 24169.655 | H25: =G25/E25*100 -> 46.949602
... A29: 60000 | B29: =$B$34 -> 8000 | C29: =$B$35/1000*A29 -> 42000 | D29: =B29+C29 -> 50000 | E29: =A29*$B$36/1000 -> 59400 | F29: =E29-D29 -> 9400 | G29: =E29-$E$13 -> 32089.655 | H29: =G29/E29*100 -> 54.022989
A31: Example (conditional)
A32: Data for graph development
A33: Payback point (break-even production volume), products | B33: =B34*1000/(B36-B35) -> 27586.207
A34: Fixed costs, thousand $ | B34: 8000
A35: Variable costs, $/product | B35: 700
A36: Price, $/product | B36: 990
A37: Release of products according to plan, products | B37: 38000

Sheet 1
A1: Объем производства, шт | B1: Зпост, тыс. руб. | C1: Зпер, тыс. руб/шт | D1: Зитого | E1: Выручка.общ, тыс. руб. | F1: Прибыль, тыс. руб. | G1: Кромка безопасности, тыс. руб. (Выручка ф(пл) - Выручка в точке безуб) | H1: Кромка безопасности, % (Кромка безопасности, тыс. руб./Выручка, тыс. руб.*100)
A2: The volume of production, products | B2: Fixed costs, thousand $ | C2: Variable costs, thousand $ | D2: Total cost, thousand $ | E2: Revenue from product sales, thousand $ | F2: Profit, thousand $ | G2: Financial strength margin, thousand $ (Actual revenue from product sales - Revenue from product sales at the break-even point) | H2: Financial strength margin, % (Financial strength margin/Revenue from product sales*100)
A3: 2000
A4: 2200
A5: 2500
A6: =[2]English!B30 -> 2697.6113
A7: 3000
A8: 3500
A9: 4000
A10: 4800
A11: 5000
A12: 5200
A13: 6000
A15: Payback point (break-even production volume), products
A16: Fixed costs, $
A17: Variable costs, $/product
A18: Price, $/product
A19: Release of products according to plan, products

Sheet 2
A1: Объем производства, шт | B1: Зпост, тыс. руб. | C1: Зпер, тыс. руб/шт | D1: Зитого | E1: Выручка.общ, тыс. руб. | F1: Прибыль, тыс. руб. | G1: Кромка безопасности, тыс. руб. (Выручка ф(пл) - Выручка в точке безуб) | H1: Кромка безопасности, % (Кромка безопасности, тыс. руб./Выручка, тыс. руб.*100)
A2: The volume of production, products | B2: Fixed costs, thousand $ | C2: Variable costs, thousand $ | D2: Total cost, thousand $ | E2: Revenue from product sales, thousand $ | F2: Profit, thousand $ | G2: Financial strength margin, thousand $ (Actual revenue from product sales - Revenue from product sales at the break-even point) | H2: Financial strength margin, % (Financial strength margin/Revenue from product sales*100)
A3: 2000
A4: 2500
A5: 3000
A6: =[2]English!C30 -> 3976.1203
A7: 4200
A8: 5000
A9: 5500
A10: 6000
A11: 6500
A12: 7000
A13: 7500
A15: Payback point (break-even production volume), products
A16: Fixed costs, $
A17: Variable costs, $/product
A18: Price, $/product
A19: Release of products according to plan, products

Sheet 3
A1: Объем производства, шт | B1: Зпост, тыс. руб. | C1: Зпер, тыс. руб/шт | D1: Зитого | E1: Выручка.общ, тыс. руб. | F1: Прибыль, тыс. руб. | G1: Кромка безопасности, тыс. руб. (Выручка ф(пл) - Выручка в точке безуб) | H1: Кромка безопасности, % (Кромка безопасности, тыс. руб./Выручка, тыс. руб.*100)
A2: The volume of production, products | B2: Fixed costs, thousand $ | C2: Variable costs, thousand $ | D2: Total cost, thousand $ | E2: Revenue from product sales, thousand $ | F2: Profit, thousand $ | G2: Financial strength margin, thousand $ (Actual revenue from product sales - Revenue from product sales at the break-even point) | H2: Financial strength margin, % (Financial strength margin/Revenue from product sales*100)
A3: 2000
A4: 2500
A5: 3000
A6: =[2]English!D30 -> 3350.8048
A7: 4000
A8: 4500
A9: 5000
A10: 7200
A11: 8000
A12: 8500
A13: 9000
A15: Payback point (break-even production volume), products
A16: Fixed costs, $
A17: Variable costs, $/product
A18: Price, $/product
A19: Release of products according to plan, products

Sheet 4
A1: Объем производства, шт | B1: Зпост, тыс. руб. | C1: Зпер, тыс. руб/шт | D1: Зитого | E1: Выручка.общ, тыс. руб. | F1: Прибыль, тыс. руб. | G1: Кромка безопасности, тыс. руб. (Выручка ф(пл) - Выручка в точке безуб) | H1: Кромка безопасности, % (Кромка безопасности, тыс. руб./Выручка, тыс. руб.*100)
A2: The volume of production, products | B2: Fixed costs, thousand $ | C2: Variable costs, thousand $ | D2: Total cost, thousand $ | E2: Revenue from product sales, thousand $ | F2: Profit, thousand $ | G2: Financial strength margin, thousand $ (Actual revenue from product sales - Revenue from product sales at the break-even point) | H2: Financial strength margin, % (Financial strength margin/Revenue from product sales*100)
A3: 2000
A4: 3000
A5: 4500
A6: =[2]English!E30 -> 5502.2309
A7: 6000
A8: 10000
A9: 20000
A10: 50000
A11: 60000
A12: 70000
A13: 80000
A15: Payback point (break-even production volume), products
A16: Fixed costs, $
A17: Variable costs, $/product
A18: Price, $/product
A19: Release of products according to plan, products

Sheet 5
A1: Объем производства, шт | B1: Зпост, тыс. руб. | C1: Зпер, тыс. руб/шт | D1: Зитого | E1: Выручка.общ, тыс. руб. | F1: Прибыль, тыс. руб. | G1: Кромка безопасности, тыс. руб. (Выручка ф(пл) - Выручка в точке безуб) | H1: Кромка безопасности, % (Кромка безопасности, тыс. руб./Выручка, тыс. руб.*100)
A2: The volume of production, products | B2: Fixed costs, thousand $ | C2: Variable costs, thousand $ | D2: Total cost, thousand $ | E2: Revenue from product sales, thousand $ | F2: Profit, thousand $ | G2: Financial strength margin, thousand $ (Actual revenue from product sales - Revenue from product sales at the break-even point) | H2: Financial strength margin, % (Financial strength margin/Revenue from product sales*100)
A3: 1500
A4: 1800
A5: 2000
A6: =[2]English!F30 -> 2649.5081
A7: 3000
A8: 3500
A9: 3800
A10: 4500
A11: 4800
A12: 5000
A13: 5200
A15: Payback point (break-even production volume), products
A16: Fixed costs, $
A17: Variable costs, $/product
A18: Price, $/product
A19: Release of products according to plan, products

Sheet 6
A1: Объем производства, шт | B1: Зпост, тыс. руб. | C1: Зпер, тыс. руб/шт | D1: Зитого | E1: Выручка.общ, тыс. руб. | F1: Прибыль, тыс. руб. | G1: Кромка безопасности, тыс. руб. (Выручка ф(пл) - Выручка в точке безуб) | H1: Кромка безопасности, % (Кромка безопасности, тыс. руб./Выручка, тыс. руб.*100)
A2: 2000 | B2: =$B$15/1000 -> 70.9508 | C2: =$B$16/1000*A2 -> 162.79683 | D2: =SUM(B2:C2) -> 233.74763 | E2: =A2*$B$17/1000 -> 203.85298 | F2: =E2-D2 -> -29.894648 | G2: =E2-$E$5 -> -148.43361 | H2: =G2/E2*100 -> -72.814051
A3: 2500 | B3: =$B$15/1000 -> 70.9508 | C3: =$B$16/1000*A3 -> 203.49603 | D3: =SUM(B3:C3) -> 274.44683 | E3: =A3*$B$17/1000 -> 254.81622 | F3: =E3-D3 -> -19.63061 | G3: =E3-$E$5 -> -97.470366 | H3: =G3/E3*100 -> -38.251241
A4: 3000 | B4: =$B$15/1000 -> 70.9508 | C4: =$B$16/1000*A4 -> 244.19524 | D4: =SUM(B4:C4) -> 315.14604 | E4: =A4*$B$17/1000 -> 305.77947 | F4: =E4-D4 -> -9.3665714 | G4: =E4-$E$5 -> -46.507122 | H4: =G4/E4*100 -> -15.209367
A5: =[2]English!G30 -> 3456.281 | B5: =$B$15/1000 -> 70.9508 | C5: =$B$16/1000*A5 -> 281.33579 | D5: =SUM(B5:C5) -> 352.28659 | E5: =A5*$B$17/1000 -> 352.28659 | F5: =E5-D5 -> 0 | G5: =E5-$E$5 -> 0 | H5: =G5/E5*100 -> 0
A6: 4000 | B6: =$B$15/1000 -> 70.9508 | C6: =$B$16/1000*A6 -> 325.59365 | D6: =SUM(B6:C6) -> 396.54445 | E6: =A6*$B$17/1000 -> 407.70596 | F6: =E6-D6 -> 11.161505 | G6: =E6-$E$5 -> 55.419367 | H6: =G6/E6*100 -> 13.592975
A7: 4500 | B7: =$B$15/1000 -> 70.9508 | C7: =$B$16/1000*A7 -> 366.29286 | D7: =SUM(B7:C7) -> 437.24366 | E7: =A7*$B$17/1000 -> 458.6692 | F7: =E7-D7 -> 21.425543 | G7: =E7-$E$5 -> 106.38261 | H7: =G7/E7*100 -> 23.193755
A8: 5000 | B8: =$B$15/1000 -> 70.9508 | C8: =$B$16/1000*A8 -> 406.99206 | D8: =SUM(B8:C8) -> 477.94286 | E8: =A8*$B$17/1000 -> 509.63244 | F8: =E8-D8 -> 31.689581 | G8: =E8-$E$5 -> 157.34586 | H8: =G8/E8*100 -> 30.87438
A9: 6300 | B9: =$B$15/1000 -> 70.9508 | C9: =$B$16/1000*A9 -> 512.81 | D9: =SUM(B9:C9) -> 583.7608 | E9: =A9*$B$17/1000 -> 642.13688 | F9: =E9-D9 -> 58.37608 | G9: =E9-$E$5 -> 289.85029 | H9: =G9/E9*100 -> 45.138397
A10: 7000 | B10: =$B$15/1000 -> 70.9508 | C10: =$B$16/1000*A10 -> 569.78889 | D10: =SUM(B10:C10) -> 640.73969 | E10: =A10*$B$17/1000 -> 713.48542 | F10: =E10-D10 -> 72.745733 | G10: =E10-$E$5 -> 361.19883 | H10: =G10/E10*100 -> 50.624557
A11: 7500 | B11: =$B$15/1000 -> 70.9508 | C11: =$B$16/1000*A11 -> 610.4881 | D11: =SUM(B11:C11) -> 681.4389 | E11: =A11*$B$17/1000 -> 764.44867 | F11: =E11-D11 -> 83.009771 | G11: =E11-$E$5 -> 412.16208 | H11: =G11/E11*100 -> 53.916253
A12: 8000 | B12: =$B$15/1000 -> 70.9508 | C12: =$B$16/1000*A12 -> 651.1873 | D12: =SUM(B12:C12) -> 722.1381 | E12: =A12*$B$17/1000 -> 815.41191 | F12: =E12-D12 -> 93.27381 | G12: =E12-$E$5 -> 463.12532 | H12: =G12/E12*100 -> 56.796487
A14: Payback point (break-even production volume), products | B14: =Русский!G29 -> 3456.281
A15: Fixed costs, $ | B15: =Русский!G27 -> 70950.8
A16: Variable costs, $/product | B16: =Русский!G28 -> 81.398413
A17: Price, $/product | B17: =Русский!G26 -> 101.92649
A18: Release of products according to plan, products | B18: =Русский!G4 -> 6300

Sheet 7
A1: Объем производства, шт | B1: Зпост, тыс. руб. | C1: Зпер, тыс. руб/шт | D1: Зитого | E1: Выручка.общ, тыс. руб. | F1: Прибыль, тыс. руб. | G1: Кромка безопасности, тыс. руб. (Выручка ф(пл) - Выручка в точке безуб) | H1: Кромка безопасности, % (Кромка безопасности, тыс. руб./Выручка, тыс. руб.*100)
A2: The volume of production, products | B2: Fixed costs, thousand $ | C2: Variable costs, thousand $ | D2: Total cost, thousand $ | E2: Revenue from product sales, thousand $ | F2: Profit, thousand $ | G2: Financial strength margin, thousand $ (Actual revenue from product sales - Revenue from product sales at the break-even point) | H2: Financial strength margin, % (Financial strength margin/Revenue from product sales*100)
A3: 1500
A4: 1800
A5: 2000
A6: =[2]English!H30 -> 2041.1133
A7: 2200
A8: 3000
A9: 4000
A10: 7000
A11: 8000
A12: 9000
A13: 10000
A15: Payback point (break-even production volume), products
A16: Fixed costs, $
A17: Variable costs, $/product
A18: Price, $/product
A19: Release of products according to plan, products

Sheet 8
A1: Объем производства, шт | B1: Зпост, тыс. руб. | C1: Зпер, тыс. руб/шт | D1: Зитого | E1: Выручка.общ, тыс. руб. | F1: Прибыль, тыс. руб. | G1: Кромка безопасности, тыс. руб. (Выручка ф(пл) - Выручка в точке безуб) | H1: Кромка безопасности, % (Кромка безопасности, тыс. руб./Выручка, тыс. руб.*100)
A2: The volume of production, products | B2: Fixed costs, thousand $ | C2: Variable costs, thousand $ | D2: Total cost, thousand $ | E2: Revenue from product sales, thousand $ | F2: Profit, thousand $ | G2: Financial strength margin, thousand $ (Actual revenue from product sales - Revenue from product sales at the break-even point) | H2: Financial strength margin, % (Financial strength margin/Revenue from product sales*100)
A3: 1300
A4: 1500
A5: 1600
A6: =[2]English!I30 -> 1807.4998
A7: 2000
A8: 3000
A9: 4000
A10: 6000
A11: 7000
A12: 8000
A13: 9000
A15: Payback point (break-even production volume), products
A16: Fixed costs, $
A17: Variable costs, $/product
A18: Price, $/product
A19: Release of products according to plan, products

Sheet 9
A1: Объем производства, шт | B1: Зпост, тыс. руб. | C1: Зпер, тыс. руб/шт | D1: Зитого | E1: Выручка.общ, тыс. руб. | F1: Прибыль, тыс. руб. | G1: Кромка безопасности, тыс. руб. (Выручка ф(пл) - Выручка в точке безуб) | H1: Кромка безопасности, % (Кромка безопасности, тыс. руб./Выручка, тыс. руб.*100)
A2: The volume of production, products | B2: Fixed costs, thousand $ | C2: Variable costs, thousand $ | D2: Total cost, thousand $ | E2: Revenue from product sales, thousand $ | F2: Profit, thousand $ | G2: Financial strength margin, thousand $ (Actual revenue from product sales - Revenue from product sales at the break-even point) | H2: Financial strength margin, % (Financial strength margin/Revenue from product sales*100)
A3: 1000
A4: 1100
A5: 1200
A6: =[2]English!J30 -> 1386.2245
A7: 1500
A8: 3000
A9: 4000
A10: 5500
A11: 6000
A12: 7000
A13: 8000
A15: Payback point (break-even production volume), products
A16: Fixed costs, $
A17: Variable costs, $/product
A18: Price, $/product
A19: Release of products according to plan, products

Sheet 10
A1: Объем производства, шт | B1: Зпост, тыс. руб. | C1: Зпер, тыс. руб/шт | D1: Зитого | E1: Выручка.общ, тыс. руб. | F1: Прибыль, тыс. руб. | G1: Кромка безопасности, тыс. руб. (Выручка ф(пл) - Выручка в точке безуб) | H1: Кромка безопасности, % (Кромка безопасности, тыс. руб./Выручка, тыс. руб.*100)
A2: The volume of production, products | B2: Fixed costs, thousand $ | C2: Variable costs, thousand $ | D2: Total cost, thousand $ | E2: Revenue from product sales, thousand $ | F2: Profit, thousand $ | G2: Financial strength margin, thousand $ (Actual revenue from product sales - Revenue from product sales at the break-even point) | H2: Financial strength margin, % (Financial strength margin/Revenue from product sales*100)
A3: 1500
A4: 2000
A5: 2500
A6: =[2]English!K30 -> 2511.3707
A7: 3000
A8: 3500
A9: 5000
A10: 7400
A11: 8000
A12: 9000
A13: 10000
A15: Payback point (break-even production volume), products
A16: Fixed costs, thousand $
A17: Variable costs, $/product
A18: Price, $/product
A19: Release of products according to plan, products
